Workbook

Sheet Data Entry
A1: Date | B1: Time | C1: Age | D1: History/Mechanism of injury | E1: Cause of injury | F1: Site | G1: Type of program | H1: Specific injuries treated | I1: Priority Of Pt | J1: Hospital Transportation | K1: Month | L1: Hour | M1: Time Period | N1: Day of Week | O1: Week Number | P1: Quarter | W1: Date | X1: Program type | Y1: Quarter
A2: 45902 | B2: 0.69444444 | C2: 22 | D2: Player-to-Player | E2: Activity | F2: 5 A side | G2: Afternoon Program | H2: Arm | I2: P3 | J2: NO | K2: =TEXT(A2,"MMM-YY") | L2: =HOUR(B2) | M2: =IF(L2<6,"Night",IF(L2<12,"Morning",IF(L2<18,"Afternoon","Evening"))) | N2: =TEXT(A2,"DDD") | O2: =WEEKNUM(A2) | P2: =INDEX({"Q1","Q1","Q1","Q2","Q2","Q2","Q3","Q3","Q3","Q4","Q4","Q4"},MONTH(A2)) | U2: Priority of patient | W2: 45931 | X2: Bystander | Y2: =INDEX({"Q3","Q3","Q4","Q4","Q4","Q1","Q1","Q1","Q2","Q2","Q2","Q3"},MONTH(#REF!)) | Z2: Activity
A3: 45906 | B3: 0.55902778 | C3: 10 | D3: Player-to-Player | E3: Activity | F3: 5 A side | G3: Open Play | H3: Knee | I3: P3 | J3: NO | K3: =TEXT(A3,"MMM-YY") | L3: =HOUR(B3) | M3: =IF(L3<6,"Night",IF(L3<12,"Morning",IF(L3<18,"Afternoon","Evening"))) | N3: =TEXT(A3,"DDD") | O3: =WEEKNUM(A3) | P3: =INDEX({"Q1","Q1","Q1","Q2","Q2","Q2","Q3","Q3","Q3","Q4","Q4","Q4"},MONTH(A3)) | U3: P1 | W3: 45932 | X3: Training | Z3: Equipment
A4: 45907 | B4: 0.52777778 | C4: 15 | D4: Slips, Trips and falls | E4: Activity | F4: 11- A side | G4: Open Play | H4: Elbow | I4: P3 | J4: NO | K4: =TEXT(A4,"MMM-YY") | L4: =HOUR(B4) | M4: =IF(L4<6,"Night",IF(L4<12,"Morning",IF(L4<18,"Afternoon","Evening"))) | N4: =TEXT(A4,"DDD") | O4: =WEEKNUM(A4) | P4: =INDEX({"Q1","Q1","Q1","Q2","Q2","Q2","Q3","Q3","Q3","Q4","Q4","Q4"},MONTH(A4)) | U4: P2 | W4: 45933 | X4: Yoga | Z4: Enviroment
A5: 45907 | B5: 0.57638889 | C5: 15 | D5: Player-to-Player | E5: Activity | F5: 11- A side | G5: Open Play | H5: Knee | I5: P3 | J5: NO | K5: =TEXT(A5,"MMM-YY") | L5: =HOUR(B5) | M5: =IF(L5<6,"Night",IF(L5<12,"Morning",IF(L5<18,"Afternoon","Evening"))) | N5: =TEXT(A5,"DDD") | O5: =WEEKNUM(A5) | P5: =INDEX({"Q1","Q1","Q1","Q2","Q2","Q2","Q3","Q3","Q3","Q4","Q4","Q4"},MONTH(A5)) | U5: P3 | W5: 45934 | X5: Girl Skate | Z5: NONE SPORTS CENTER
A6: 45907 | B6: 0.65 | C6: 14 | D6: Slips, Trips and falls | E6: NONE SPORTS CENTER | F6: 11- A side | G6: NONE SPORTS CENTER | H6: Knee | I6: P3 | J6: NO | K6: =TEXT(A6,"MMM-YY") | L6: =HOUR(B6) | M6: =IF(L6<6,"Night",IF(L6<12,"Morning",IF(L6<18,"Afternoon","Evening"))) | N6: =TEXT(A6,"DDD") | O6: =WEEKNUM(A6) | P6: =INDEX({"Q1","Q1","Q1","Q2","Q2","Q2","Q3","Q3","Q3","Q4","Q4","Q4"},MONTH(A6)) | U6: P4 | W6: 45935 | X6: Kicking Boxing
A7: 45908 | B7: 0.60416667 | C7: 19 | D7: Player-to-Player | E7: Activity | F7: 11- A side | G7: Open Play | H7: Ankle | I7: P3 | J7: NO | K7: =TEXT(A7,"MMM-YY") | L7: =HOUR(B7) | M7: =IF(L7<6,"Night",IF(L7<12,"Morning",IF(L7<18,"Afternoon","Evening"))) | N7: =TEXT(A7,"DDD") | O7: =WEEKNUM(A7) | P7: =INDEX({"Q1","Q1","Q1","Q2","Q2","Q2","Q3","Q3","Q3","Q4","Q4","Q4"},MONTH(A7)) | U7: Hospital Transportation | W7: 45936 | X7: Running with the pack
A8: 45908 | B8: 0.66666667 | C8: 10 | D8: Slips, Trips and falls | E8: Activity | F8: Skate Park | G8: Girl Skate | H8: Shoulder | I8: P3 | J8: NO | K8: =TEXT(A8,"MMM-YY") | L8: =HOUR(B8) | M8: =IF(L8<6,"Night",IF(L8<12,"Morning",IF(L8<18,"Afternoon","Evening"))) | N8: =TEXT(A8,"DDD") | O8: =WEEKNUM(A8) | P8: =INDEX({"Q1","Q1","Q1","Q2","Q2","Q2","Q3","Q3","Q3","Q4","Q4","Q4"},MONTH(A8)) | U8: YES | W8: 45937 | X8: Dancing
A9: 45914 | B9: 0.54166667 | C9: 13 | D9: Medical | E9: Activity | F9: 11- A side | G9: Open Play | H9: Medical | I9: P3 | J9: NO | K9: =TEXT(A9,"MMM-YY") | L9: =HOUR(B9) | M9: =IF(L9<6,"Night",IF(L9<12,"Morning",IF(L9<18,"Afternoon","Evening"))) | N9: =TEXT(A9,"DDD") | O9: =WEEKNUM(A9) | P9: =INDEX({"Q1","Q1","Q1","Q2","Q2","Q2","Q3","Q3","Q3","Q4","Q4","Q4"},MONTH(A9)) | U9: NO | W9: 45938 | X9: LFA
A10: 45915 | B10: 0.5625 | C10: 19 | D10: Player-to-Player | E10: Activity | F10: 5 A side | G10: Open Play | H10: Foot | I10: P3 | J10: NO | K10: =TEXT(A10,"MMM-YY") | L10: =HOUR(B10) | M10: =IF(L10<6,"Night",IF(L10<12,"Morning",IF(L10<18,"Afternoon","Evening"))) | N10: =TEXT(A10,"DDD") | O10: =WEEKNUM(A10) | P10: =INDEX({"Q1","Q1","Q1","Q2","Q2","Q2","Q3","Q3","Q3","Q4","Q4","Q4"},MONTH(A10)) | W10: 45939 | X10: Morning Show
A11: 45919 | B11: 0.70069444 | C11: 14 | D11: Struck by Equipment | E11: Activity | F11: 11- A side | G11: Open Play | H11: Facial Injury | I11: P3 | J11: NO | K11: =TEXT(A11,"MMM-YY") | L11: =HOUR(B11) | M11: =IF(L11<6,"Night",IF(L11<12,"Morning",IF(L11<18,"Afternoon","Evening"))) | N11: =TEXT(A11,"DDD") | O11: =WEEKNUM(A11) | P11: =INDEX({"Q1","Q1","Q1","Q2","Q2","Q2","Q3","Q3","Q3","Q4","Q4","Q4"},MONTH(A11)) | W11: 45940 | X11: Her Game
A12: 45921 | B12: 0.4375 | C12: 24 | D12: Muscle Strains | E12: Activity | F12: 11- A side | G12: Open Play | H12: Lower limb | I12: P3 | J12: NO | K12: =TEXT(A12,"MMM-YY") | L12: =HOUR(B12) | M12: =IF(L12<6,"Night",IF(L12<12,"Morning",IF(L12<18,"Afternoon","Evening"))) | N12: =TEXT(A12,"DDD") | O12: =WEEKNUM(A12) | P12: =INDEX({"Q1","Q1","Q1","Q2","Q2","Q2","Q3","Q3","Q3","Q4","Q4","Q4"},MONTH(A12)) | W12: 45941 | X12: FNB Tournament
A13: 45921 | B13: 0.45 | C13: 14 | D13: Player-to-Player | E13: Activity | F13: 11- A side | G13: Training | H13: Foot | I13: P3 | J13: NO | K13: =TEXT(A13,"MMM-YY") | L13: =HOUR(B13) | M13: =IF(L13<6,"Night",IF(L13<12,"Morning",IF(L13<18,"Afternoon","Evening"))) | N13: =TEXT(A13,"DDD") | O13: =WEEKNUM(A13) | P13: =INDEX({"Q1","Q1","Q1","Q2","Q2","Q2","Q3","Q3","Q3","Q4","Q4","Q4"},MONTH(A13)) | W13: 45942 | X13: OR Tambo Soncini Games
A14: 45921 | B14: 0.45 | C14: 16 | D14: Player-to-Player | E14: Activity | F14: 11- A side | G14: Open Play | H14: Ankle | I14: P3 | J14: NO | K14: =TEXT(A14,"MMM-YY") | L14: =HOUR(B14) | M14: =IF(L14<6,"Night",IF(L14<12,"Morning",IF(L14<18,"Afternoon","Evening"))) | N14: =TEXT(A14,"DDD") | O14: =WEEKNUM(A14) | P14: =INDEX({"Q1","Q1","Q1","Q2","Q2","Q2","Q3","Q3","Q3","Q4","Q4","Q4"},MONTH(A14)) | W14: 45943 | X14: Clinic Stix Morewa Challenge
A15: 45923 | B15: 0.78125 | C15: 23 | D15: Muscle Strains | E15: Activity | F15: 1KM RUN/WALK PATH | G15: Open Play | H15: Ankle | I15: P3 | J15: NO | K15: =TEXT(A15,"MMM-YY") | L15: =HOUR(B15) | M15: =IF(L15<6,"Night",IF(L15<12,"Morning",IF(L15<18,"Afternoon","Evening"))) | N15: =TEXT(A15,"DDD") | O15: =WEEKNUM(A15) | P15: =INDEX({"Q1","Q1","Q1","Q2","Q2","Q2","Q3","Q3","Q3","Q4","Q4","Q4"},MONTH(A15)) | W15: 45944 | X15: Discovery Challenge
A16: 45924 | B16: 0.4375 | C16: 22 | D16: Muscle Strains | E16: Activity | F16: 11- A side | G16: Open Play | H16: Upper limb Muscle | I16: P3 | J16: NO | K16: =TEXT(A16,"MMM-YY") | L16: =HOUR(B16) | M16: =IF(L16<6,"Night",IF(L16<12,"Morning",IF(L16<18,"Afternoon","Evening"))) | N16: =TEXT(A16,"DDD") | O16: =WEEKNUM(A16) | P16: =INDEX({"Q1","Q1","Q1","Q2","Q2","Q2","Q3","Q3","Q3","Q4","Q4","Q4"},MONTH(A16)) | W16: 45945 | X16: Afternoon Program
A17: 45925 | B17: 0.5 | C17: 21 | D17: Slips, Trips and falls | E17: Activity | F17: Basketball | G17: Open Play | H17: Ankle | I17: P3 | J17: NO | K17: =TEXT(A17,"MMM-YY") | L17: =HOUR(B17) | M17: =IF(L17<6,"Night",IF(L17<12,"Morning",IF(L17<18,"Afternoon","Evening"))) | N17: =TEXT(A17,"DDD") | O17: =WEEKNUM(A17) | P17: =INDEX({"Q1","Q1","Q1","Q2","Q2","Q2","Q3","Q3","Q3","Q4","Q4","Q4"},MONTH(A17)) | W17: 45946 | X17: Open Play
A18: 45937 | B18: 0.58055556 | C18: 13 | D18: Slips, Trips and falls | E18: Activity | F18: 11- A side | G18: Training | H18: Hand | I18: P3 | J18: NO | K18: =TEXT(A18,"MMM-YY") | L18: =HOUR(B18) | M18: =IF(L18<6,"Night",IF(L18<12,"Morning",IF(L18<18,"Afternoon","Evening"))) | N18: =TEXT(A18,"DDD") | O18: =WEEKNUM(A18) | P18: =INDEX({"Q1","Q1","Q1","Q2","Q2","Q2","Q3","Q3","Q3","Q4","Q4","Q4"},MONTH(A18)) | W18: 45947 | X18: Cause of injury
A19: 45937 | B19: 0.60902778 | C19: 14 | D19: Player-to-Player | E19: Activity | F19: 11- A side | G19: Training | H19: Arm | I19: P3 | J19: NO | K19: =TEXT(A19,"MMM-YY") | L19: =HOUR(B19) | M19: =IF(L19<6,"Night",IF(L19<12,"Morning",IF(L19<18,"Afternoon","Evening"))) | N19: =TEXT(A19,"DDD") | O19: =WEEKNUM(A19) | P19: =INDEX({"Q1","Q1","Q1","Q2","Q2","Q2","Q3","Q3","Q3","Q4","Q4","Q4"},MONTH(A19)) | W19: 45948 | X19: Activity
A20: 45938 | B20: 0.63888889 | C20: 10 | D20: Player-to-Player | E20: Activity | F20: Athletics track | G20: Afternoon Program | H20: Facial Injury | I20: P3 | J20: NO | K20: =TEXT(A20,"MMM-YY") | L20: =HOUR(B20) | M20: =IF(L20<6,"Night",IF(L20<12,"Morning",IF(L20<18,"Afternoon","Evening"))) | N20: =TEXT(A20,"DDD") | O20: =WEEKNUM(A20) | P20: =INDEX({"Q1","Q1","Q1","Q2","Q2","Q2","Q3","Q3","Q3","Q4","Q4","Q4"},MONTH(A20)) | W20: 45949 | X20: Equipment
A21: 45939 | B21: 0.58888889 | C21: 15 | D21: Player-to-Object | E21: Equipment | F21: 5 A side | G21: Open Play | H21: Wrist | I21: P3 | J21: NO | K21: =TEXT(A21,"MMM-YY") | L21: =HOUR(B21) | M21: =IF(L21<6,"Night",IF(L21<12,"Morning",IF(L21<18,"Afternoon","Evening"))) | N21: =TEXT(A21,"DDD") | O21: =WEEKNUM(A21) | P21: =INDEX({"Q1","Q1","Q1","Q2","Q2","Q2","Q3","Q3","Q3","Q4","Q4","Q4"},MONTH(A21)) | W21: 45950 | X21: Enviroment
A22: 45940 | B22: 0.58541667 | C22: 22 | D22: Player-to-Player | E22: Activity | F22: Outdoor gym | G22: Open Play | H22: Knee | I22: P3 | J22: NO | K22: =TEXT(A22,"MMM-YY") | L22: =HOUR(B22) | M22: =IF(L22<6,"Night",IF(L22<12,"Morning",IF(L22<18,"Afternoon","Evening"))) | N22: =TEXT(A22,"DDD") | O22: =WEEKNUM(A22) | P22: =INDEX({"Q1","Q1","Q1","Q2","Q2","Q2","Q3","Q3","Q3","Q4","Q4","Q4"},MONTH(A22)) | W22: 45951 | X22: NONE SPORTS CENTER
A23: 45947 | B23: 0.51944444 | C23: 19 | D23: Player-to-Player | E23: Activity | F23: 11- A side | G23: Open Play | H23: Lower limb | I23: P3 | J23: NO | K23: =TEXT(A23,"MMM-YY") | L23: =HOUR(B23) | M23: =IF(L23<6,"Night",IF(L23<12,"Morning",IF(L23<18,"Afternoon","Evening"))) | N23: =TEXT(A23,"DDD") | O23: =WEEKNUM(A23) | P23: =INDEX({"Q1","Q1","Q1","Q2","Q2","Q2","Q3","Q3","Q3","Q4","Q4","Q4"},MONTH(A23)) | W23: 45952
A24: 45948 | B24: 0.69444444 | C24: 20 | D24: Muscle Strains | E24: Activity | F24: 11- A side | G24: Open Play | H24: Back | I24: P3 | J24: NO | K24: =TEXT(A24,"MMM-YY") | L24: =HOUR(B24) | M24: =IF(L24<6,"Night",IF(L24<12,"Morning",IF(L24<18,"Afternoon","Evening"))) | N24: =TEXT(A24,"DDD") | O24: =WEEKNUM(A24) | P24: =INDEX({"Q1","Q1","Q1","Q2","Q2","Q2","Q3","Q3","Q3","Q4","Q4","Q4"},MONTH(A24)) | W24: 45953
A25: 45952 | B25: 0.55902778 | C25: 40 | D25: Struck by Equipment | E25: Activity | F25: Change Rooms | G25: Open Play | H25: Hand | I25: P3 | J25: NO | K25: =TEXT(A25,"MMM-YY") | L25: =HOUR(B25) | M25: =IF(L25<6,"Night",IF(L25<12,"Morning",IF(L25<18,"Afternoon","Evening"))) | N25: =TEXT(A25,"DDD") | O25: =WEEKNUM(A25) | P25: =INDEX({"Q1","Q1","Q1","Q2","Q2","Q2","Q3","Q3","Q3","Q4","Q4","Q4"},MONTH(A25)) | W25: 45954
A26: 45952 | B26: 0.67638889 | C26: 12 | D26: Player-to-Player | E26: Activity | F26: 11- A side | G26: Open Play | H26: Knee | I26: P3 | J26: NO | K26: =TEXT(A26,"MMM-YY") | L26: =HOUR(B26) | M26: =IF(L26<6,"Night",IF(L26<12,"Morning",IF(L26<18,"Afternoon","Evening"))) | N26: =TEXT(A26,"DDD") | O26: =WEEKNUM(A26) | P26: =INDEX({"Q1","Q1","Q1","Q2","Q2","Q2","Q3","Q3","Q3","Q4","Q4","Q4"},MONTH(A26)) | W26: 45955
A27: 45958 | B27: 0.73680556 | C27: 14 | D27: Slips, Trips and falls | E27: Activity | F27: Skate Park | G27: Girl Skate | H27: Wrist | I27: P3 | J27: NO | K27: =TEXT(A27,"MMM-YY") | L27: =HOUR(B27) | M27: =IF(L27<6,"Night",IF(L27<12,"Morning",IF(L27<18,"Afternoon","Evening"))) | N27: =TEXT(A27,"DDD") | O27: =WEEKNUM(A27) | P27: =INDEX({"Q1","Q1","Q1","Q2","Q2","Q2","Q3","Q3","Q3","Q4","Q4","Q4"},MONTH(A27)) | W27: 45956
A28: 45960 | B28: 0.72638889 | C28: 19 | D28: Player-to-Object | E28: Equipment | F28: 5 A side | G28: Open Play | H28: Facial Injury | I28: P3 | J28: NO | K28: =TEXT(A28,"MMM-YY") | L28: =HOUR(B28) | M28: =IF(L28<6,"Night",IF(L28<12,"Morning",IF(L28<18,"Afternoon","Evening"))) | N28: =TEXT(A28,"DDD") | O28: =WEEKNUM(A28) | P28: =INDEX({"Q1","Q1","Q1","Q2","Q2","Q2","Q3","Q3","Q3","Q4","Q4","Q4"},MONTH(A28)) | W28: 45957
K29: =TEXT(A29,"MMM-YY") | L29: =HOUR(B29) | M29: =IF(L29<6,"Night",IF(L29<12,"Morning",IF(L29<18,"Afternoon","Evening"))) | N29: =TEXT(A29,"DDD") | O29: =WEEKNUM(A29) | P29: =INDEX({"Q1","Q1","Q1","Q2","Q2","Q2","Q3","Q3","Q3","Q4","Q4","Q4"},MONTH(A29)) | W29: 45958
K30: =TEXT(A30,"MMM-YY") | L30: =HOUR(B30) | M30: =IF(L30<6,"Night",IF(L30<12,"Morning",IF(L30<18,"Afternoon","Evening"))) | N30: =TEXT(A30,"DDD") | O30: =WEEKNUM(A30) | P30: =INDEX({"Q1","Q1","Q1","Q2","Q2","Q2","Q3","Q3","Q3","Q4","Q4","Q4"},MONTH(A30)) | W30: 45959
K31: =TEXT(A31,"MMM-YY") | L31: =HOUR(B31) | M31: =IF(L31<6,"Night",IF(L31<12,"Morning",IF(L31<18,"Afternoon","Evening"))) | N31: =TEXT(A31,"DDD") | O31: =WEEKNUM(A31) | P31: =INDEX({"Q1","Q1","Q1","Q2","Q2","Q2","Q3","Q3","Q3","Q4","Q4","Q4"},MONTH(A31)) | W31: 45960
K32: =TEXT(A32,"MMM-YY") | L32: =HOUR(B32) | M32: =IF(L32<6,"Night",IF(L32<12,"Morning",IF(L32<18,"Afternoon","Evening"))) | N32: =TEXT(A32,"DDD") | O32: =WEEKNUM(A32) | P32: =INDEX({"Q1","Q1","Q1","Q2","Q2","Q2","Q3","Q3","Q3","Q4","Q4","Q4"},MONTH(A32)) | W32: 45961
K33: =TEXT(A33,"MMM-YY") | L33: =HOUR(B33) | M33: =IF(L33<6,"Night",IF(L33<12,"Morning",IF(L33<18,"Afternoon","Evening"))) | N33: =TEXT(A33,"DDD") | O33: =WEEKNUM(A33) | P33: =INDEX({"Q1","Q1","Q1","Q2","Q2","Q2","Q3","Q3","Q3","Q4","Q4","Q4"},MONTH(A33))
K34: =TEXT(A34,"MMM-YY") | L34: =HOUR(B34) | M34: =IF(L34<6,"Night",IF(L34<12,"Morning",IF(L34<18,"Afternoon","Evening"))) | N34: =TEXT(A34,"DDD") | O34: =WEEKNUM(A34) | P34: =INDEX({"Q1","Q1","Q1","Q2","Q2","Q2","Q3","Q3","Q3","Q4","Q4","Q4"},MONTH(A34))
K35: =TEXT(A35,"MMM-YY") | L35: =HOUR(B35) | M35: =IF(L35<6,"Night",IF(L35<12,"Morning",IF(L35<18,"Afternoon","Evening"))) | N35: =TEXT(A35,"DDD") | O35: =WEEKNUM(A35) | P35: =INDEX({"Q1","Q1","Q1","Q2","Q2","Q2","Q3","Q3","Q3","Q4","Q4","Q4"},MONTH(A35))
K36: =TEXT(A36,"MMM-YY") | L36: =HOUR(B36) | M36: =IF(L36<6,"Night",IF(L36<12,"Morning",IF(L36<18,"Afternoon","Evening"))) | N36: =TEXT(A36,"DDD") | O36: =WEEKNUM(A36) | P36: =INDEX({"Q1","Q1","Q1","Q2","Q2","Q2","Q3","Q3","Q3","Q4","Q4","Q4"},MONTH(A36))
K37: =TEXT(A37,"MMM-YY") | L37: =HOUR(B37) | M37: =IF(L37<6,"Night",IF(L37<12,"Morning",IF(L37<18,"Afternoon","Evening"))) | N37: =TEXT(A37,"DDD") | O37: =WEEKNUM(A37) | P37: =INDEX({"Q1","Q1","Q1","Q2","Q2","Q2","Q3","Q3","Q3","Q4","Q4","Q4"},MONTH(A37))
K38: =TEXT(A38,"MMM-YY") | L38: =HOUR(B38) | M38: =IF(L38<6,"Night",IF(L38<12,"Morning",IF(L38<18,"Afternoon","Evening"))) | N38: =TEXT(A38,"DDD") | O38: =WEEKNUM(A38) | P38: =INDEX({"Q1","Q1","Q1","Q2","Q2","Q2","Q3","Q3","Q3","Q4","Q4","Q4"},MONTH(A38))
K39: =TEXT(A39,"MMM-YY") | L39: =HOUR(B39) | M39: =IF(L39<6,"Night",IF(L39<12,"Morning",IF(L39<18,"Afternoon","Evening"))) | N39: =TEXT(A39,"DDD") | O39: =WEEKNUM(A39) | P39: =INDEX({"Q1","Q1","Q1","Q2","Q2","Q2","Q3","Q3","Q3","Q4","Q4","Q4"},MONTH(A39))
K40: =TEXT(A40,"MMM-YY") | L40: =HOUR(B40) | M40: =IF(L40<6,"Night",IF(L40<12,"Morning",IF(L40<18,"Afternoon","Evening"))) | N40: =TEXT(A40,"DDD") | O40: =WEEKNUM(A40) | P40: =INDEX({"Q1","Q1","Q1","Q2","Q2","Q2","Q3","Q3","Q3","Q4","Q4","Q4"},MONTH(A40))
...

Sheet Dashboard
A1: SHAPA NIKE SOWETO MEDICAL DASHBOARD
B2: =E4
A3: REPORT CONTROLS
A4: 1. Report Type: | B4: Monthly | D4: 2. Select Month: | E4: Oct-25 | G4: 3. Select Week: | H4: Week 1 | J4: 4. Select Quarter: | K4: Q4 | M4: =VALUE(SUBSTITUTE(H4,"Week ","")) | P4: TOP RISK SITE
A5: → Monthly: Select Report Type + Month | E5: → Weekly: Select Month + Week | I5: → Quarterly: Select Quarter
A6: SUMMARY | Q6: =IFERROR(INDEX(MedicalData[Site],MODE(MATCH(MedicalData[Site],MedicalData[Site],0))),"")
A7: Period: | B7: =IF(B4="Weekly",E4&" - "&H4,IF(B4="Monthly",E4,IF(B4="Quarterly",K4&" "&RIGHT(E4,2),"All Time"))) | D7: Total Incidents | E7: =IF(B4="Weekly",SUMPRODUCT((MedicalData[Month]=E4)*(INT((DAY(MedicalData[Date])-1)/7)+1=$M$4)*1),IF(B4="Monthly",COUNTIF(MedicalData[Month],E4),IF(B4="Quarterly",COUNTIF(MedicalData[Quarter],K4),COUNTA(MedicalData[Date])))) | G7: Ambulance | H7: =IF(B4="Weekly",SUMPRODUCT((MedicalData[Month]=E4)*(INT((DAY(MedicalData[Date])-1)/7)+1=$M$4)*(MedicalData[Hospital Transportation]="Yes")*1),IF(B4="Monthly",COUNTIFS(MedicalData[Month],E4,MedicalData[Hospital Transportation],"Yes"),IF(B4="Quarterly",COUNTIFS(MedicalData[Quarter],K4,MedicalData[Hospital Transportation],"Yes"),COUNTIF(MedicalData[Hospital Transportation],"Yes")))) | J7: Avg Age | K7: =IFERROR(ROUND(IF(B4="Monthly",AVERAGEIF(MedicalData[Month],E4,MedicalData[Age]),IF(B4="Quarterly",AVERAGEIF(MedicalData[Quarter],K4,MedicalData[Age]),AVERAGE(MedicalData[Age]))),0),"-") | R7: =IF(Q6="","",COUNTIF(MedicalData[Site],Q6))
A9: TOP INJURY | F9: TOP MECHANISM | K9: PEAK TIME | P9: P3 RATE
B11: =IFERROR(INDEX(MedicalData[Specific injuries treated],MODE(MATCH(MedicalData[Specific injuries treated],MedicalData[Specific injuries treated],0))),"") | G11: =IFERROR(INDEX(MedicalData[History/Mechanism of injury],MODE(MATCH(MedicalData[History/Mechanism of injury],MedicalData[History/Mechanism of injury],0))),"") | L11: =IFERROR(INDEX(MedicalData[Time Period],MODE(MATCH(MedicalData[Time Period],MedicalData[Time Period],0))),"") | Q11: =IFERROR(TEXT(IF($B$2="All Time",COUNTIF(MedicalData[Priority Of Pt],"P3")/COUNTA(MedicalData[Date]),COUNTIFS(MedicalData[Priority Of Pt],"P3",MedicalData[Month],$B$2)/COUNTIF(MedicalData[Month],$B$2)),"0%"),"")
A14: PRIORITY BREAKDOWN
A16: P1 (Critical) | B16: =IF($B$2="All Time",COUNTIF(MedicalData[Priority Of Pt],"P1"),COUNTIFS(MedicalData[Priority Of Pt],"P1",MedicalData[Month],$B$2)) | D16: P2 (Urgent) | E16: =IF($B$2="All Time",COUNTIF(MedicalData[Priority Of Pt],"P2"),COUNTIFS(MedicalData[Priority Of Pt],"P2",MedicalData[Month],$B$2)) | G16: P3 (Standard) | H16: =IF($B$2="All Time",COUNTIF(MedicalData[Priority Of Pt],"P3"),COUNTIFS(MedicalData[Priority Of Pt],"P3",MedicalData[Month],$B$2)) | J16: P4 (Minor) | K16: =IF($B$2="All Time",COUNTIF(MedicalData[Priority Of Pt],"P4"),COUNTIFS(MedicalData[Priority Of Pt],"P4",MedicalData[Month],$B$2))
A19: QUICK INSIGHTS
A21: Busiest Day: | B21: =IFERROR(INDEX(MedicalData[Day of Week],MODE(MATCH(MedicalData[Day of Week],MedicalData[Day of Week],0))),"") | E21: Top Program: | F21: =IFERROR(INDEX(MedicalData[Type of program],MODE(MATCH(MedicalData[Type of program],MedicalData[Type of program],0))),"") | J21: Main Cause: | K21: =IFERROR(INDEX(MedicalData[Cause of injury],MODE(MATCH(MedicalData[Cause of injury],MedicalData[Cause of injury],0))),"")
A61: 🚨 AUTOMATED SAFETY ALERTS
A63: Alert 1: High-Risk Venue
B64: ="WARNING: "&INDEX(MedicalData[Site],MODE(MATCH(MedicalData[Site],MedicalData[Site],0)))&" has "&COUNTIF(MedicalData[Site],INDEX(MedicalData[Site],MODE(MATCH(MedicalData[Site],MedicalData[Site],0))))&" incidents ("&TEXT(COUNTIF(MedicalData[Site],INDEX(MedicalData[Site],MODE(MATCH(MedicalData[Site],MedicalData[Site],0))))/COUNTA(MedicalData[Date]),"0%")&" of total)"
A66: Alert 2: Ankle Injuries
B67: =IF(COUNTIF(MedicalData[Specific injuries treated],"*Ankle*")>=5,"⚠ HIGH: "&COUNTIF(MedicalData[Specific injuries treated],"*Ankle*")&" ankle injuries detected. Implement preventive measures.","✓ Ankle injury rate acceptable")
A69: Alert 3: Player Contact
B70: =IF(COUNTIF(MedicalData[History/Mechanism of injury],"Player-to-Player")>=5,"⚠ ALERT: "&COUNTIF(MedicalData[History/Mechanism of injury],"Player-to-Player")&" player-to-player incidents. Review supervision.","✓ Player contact incidents within normal range")
A72: Alert 4: Minor Involvement
B73: =IF(COUNTIFS(MedicalData[Age],"<18")>=4,"ℹ INFO: "&COUNTIFS(MedicalData[Age],"<18")&" incidents involved minors. Ensure age-appropriate safety.","✓ Minor involvement acceptable")
A76: 📋 SAFETY RECOMMENDATIONS
A78: IMMEDIATE ACTIONS | H78: PREVENTIVE MEASURES
A79: • Increase supervision at highest-risk venue | H79: • Mandatory warm-up demonstrations
A80: • Review ankle support equipment | H80: • Pre-activity equipment checks
A81: • Enhanced safety briefings | H81: • Surface inspection protocols
A82: • Install additional signage | H82: • Age-appropriate activity segregation
A83: • Conduct facility safety audit | H83: • Monthly safety training
A84: • Review incident response times | H84: • Update emergency procedures
A88: =IF(B4="Weekly","WEEKLY BREAKDOWN: "&E4&" - "&H4,IF(B4="Monthly","MONTHLY BREAKDOWN: "&E4,"QUARTERLY BREAKDOWN: "&K4))
A90: Day/Week | B90: Incidents | C90: Ambulance | D90: Avg Age | E90: Top Injury | F90: Top Venue | G90: Top Mechanism
A91: =IF(B4="Weekly","Monday",IF(B4="Monthly","Week 1",IF(B4="Quarterly",IF(1>3,"","Month 1"),"1"))) | B91: =IF(B4="Weekly",SUMPRODUCT((MedicalData[Month]=E4)*(INT((DAY(MedicalData[Date])-1)/7)+1=$M$4)*(WEEKDAY(MedicalData[Date],2)=1)*1),IF(B4="Monthly",SUMPRODUCT((MedicalData[Month]=E4)*(INT((DAY(MedicalData[Date])-1)/7)+1=1)*1),IF(B4="Quarterly",IF(1>3,"",COUNTIF(MedicalData[Quarter],K4)),0))) | C91: =IF(B4="Weekly",SUMPRODUCT((MedicalData[Month]=E4)*(INT((DAY(MedicalData[Date])-1)/7)+1=$M$4)*(WEEKDAY(MedicalData[Date],2)=1)*(MedicalData[Hospital Transportation]="Yes")*1),IF(B4="Monthly",SUMPRODUCT((MedicalData[Month]=E4)*(INT((DAY(MedicalData[Date])-1)/7)+1=1)*(MedicalData[Hospital Transportation]="Yes")*1),IF(B4="Quarterly",IF(1>3,"",COUNTIFS(MedicalData[Quarter],K4,MedicalData[Hospital Transportation],"Yes")),0))) | D91: =IF(OR(B91=0,B91=""),"-",IFERROR(ROUND(AVERAGEIF(MedicalData[Month],E4,MedicalData[Age]),0),"-")) | E91: =IF(OR(B91=0,B91=""),"-","-") | F91: =IF(OR(B91=0,B91=""),"-","-") | G91: =IF(OR(B91=0,B91=""),"-","-")
A92: =IF(B4="Weekly","Tuesday",IF(B4="Monthly","Week 2",IF(B4="Quarterly",IF(2>3,"","Month 2"),"2"))) | B92: =IF(B4="Weekly",SUMPRODUCT((MedicalData[Month]=E4)*(INT((DAY(MedicalData[Date])-1)/7)+1=$M$4)*(WEEKDAY(MedicalData[Date],2)=2)*1),IF(B4="Monthly",SUMPRODUCT((MedicalData[Month]=E4)*(INT((DAY(MedicalData[Date])-1)/7)+1=2)*1),IF(B4="Quarterly",IF(2>3,"",COUNTIF(MedicalData[Quarter],K4)),0))) | C92: =IF(B4="Weekly",SUMPRODUCT((MedicalData[Month]=E4)*(INT((DAY(MedicalData[Date])-1)/7)+1=$M$4)*(WEEKDAY(MedicalData[Date],2)=2)*(MedicalData[Hospital Transportation]="Yes")*1),IF(B4="Monthly",SUMPRODUCT((MedicalData[Month]=E4)*(INT((DAY(MedicalData[Date])-1)/7)+1=2)*(MedicalData[Hospital Transportation]="Yes")*1),IF(B4="Quarterly",IF(2>3,"",COUNTIFS(MedicalData[Quarter],K4,MedicalData[Hospital Transportation],"Yes")),0))) | D92: =IF(OR(B92=0,B92=""),"-",IFERROR(ROUND(AVERAGEIF(MedicalData[Month],E4,MedicalData[Age]),0),"-")) | E92: =IF(OR(B92=0,B92=""),"-","-") | F92: =IF(OR(B92=0,B92=""),"-","-") | G92: =IF(OR(B92=0,B92=""),"-","-")
A93: =IF(B4="Weekly","Wednesday",IF(B4="Monthly","Week 3",IF(B4="Quarterly",IF(3>3,"","Month 3"),"3"))) | B93: =IF(B4="Weekly",SUMPRODUCT((MedicalData[Month]=E4)*(INT((DAY(MedicalData[Date])-1)/7)+1=$M$4)*(WEEKDAY(MedicalData[Date],2)=3)*1),IF(B4="Monthly",SUMPRODUCT((MedicalData[Month]=E4)*(INT((DAY(MedicalData[Date])-1)/7)+1=3)*1),IF(B4="Quarterly",IF(3>3,"",COUNTIF(MedicalData[Quarter],K4)),0))) | C93: =IF(B4="Weekly",SUMPRODUCT((MedicalData[Month]=E4)*(INT((DAY(MedicalData[Date])-1)/7)+1=$M$4)*(WEEKDAY(MedicalData[Date],2)=3)*(MedicalData[Hospital Transportation]="Yes")*1),IF(B4="Monthly",SUMPRODUCT((MedicalData[Month]=E4)*(INT((DAY(MedicalData[Date])-1)/7)+1=3)*(MedicalData[Hospital Transportation]="Yes")*1),IF(B4="Quarterly",IF(3>3,"",COUNTIFS(MedicalData[Quarter],K4,MedicalData[Hospital Transportation],"Yes")),0))) | D93: =IF(OR(B93=0,B93=""),"-",IFERROR(ROUND(AVERAGEIF(MedicalData[Month],E4,MedicalData[Age]),0),"-")) | E93: =IF(OR(B93=0,B93=""),"-","-") | F93: =IF(OR(B93=0,B93=""),"-","-") | G93: =IF(OR(B93=0,B93=""),"-","-")
A94: =IF(B4="Weekly","Thursday",IF(B4="Monthly","Week 4",IF(B4="Quarterly",IF(4>3,"","Month 4"),"4"))) | B94: =IF(B4="Weekly",SUMPRODUCT((MedicalData[Month]=E4)*(INT((DAY(MedicalData[Date])-1)/7)+1=$M$4)*(WEEKDAY(MedicalData[Date],2)=4)*1),IF(B4="Monthly",SUMPRODUCT((MedicalData[Month]=E4)*(INT((DAY(MedicalData[Date])-1)/7)+1=4)*1),IF(B4="Quarterly",IF(4>3,"",COUNTIF(MedicalData[Quarter],K4)),0))) | C94: =IF(B4="Weekly",SUMPRODUCT((MedicalData[Month]=E4)*(INT((DAY(MedicalData[Date])-1)/7)+1=$M$4)*(WEEKDAY(MedicalData[Date],2)=4)*(MedicalData[Hospital Transportation]="Yes")*1),IF(B4="Monthly",SUMPRODUCT((MedicalData[Month]=E4)*(INT((DAY(MedicalData[Date])-1)/7)+1=4)*(MedicalData[Hospital Transportation]="Yes")*1),IF(B4="Quarterly",IF(4>3,"",COUNTIFS(MedicalData[Quarter],K4,MedicalData[Hospital Transportation],"Yes")),0))) | D94: =IF(OR(B94=0,B94=""),"-",IFERROR(ROUND(AVERAGEIF(MedicalData[Month],E4,MedicalData[Age]),0),"-")) | E94: =IF(OR(B94=0,B94=""),"-","-") | F94: =IF(OR(B94=0,B94=""),"-","-") | G94: =IF(OR(B94=0,B94=""),"-","-")
A95: =IF(B4="Weekly","Friday",IF(B4="Monthly","Week 5",IF(B4="Quarterly",IF(5>3,"","Month 5"),"5"))) | B95: =IF(B4="Weekly",SUMPRODUCT((MedicalData[Month]=E4)*(INT((DAY(MedicalData[Date])-1)/7)+1=$M$4)*(WEEKDAY(MedicalData[Date],2)=5)*1),IF(B4="Monthly",SUMPRODUCT((MedicalData[Month]=E4)*(INT((DAY(MedicalData[Date])-1)/7)+1=5)*1),IF(B4="Quarterly",IF(5>3,"",COUNTIF(MedicalData[Quarter],K4)),0))) | C95: =IF(B4="Weekly",SUMPRODUCT((MedicalData[Month]=E4)*(INT((DAY(MedicalData[Date])-1)/7)+1=$M$4)*(WEEKDAY(MedicalData[Date],2)=5)*(MedicalData[Hospital Transportation]="Yes")*1),IF(B4="Monthly",SUMPRODUCT((MedicalData[Month]=E4)*(INT((DAY(MedicalData[Date])-1)/7)+1=5)*(MedicalData[Hospital Transportation]="Yes")*1),IF(B4="Quarterly",IF(5>3,"",COUNTIFS(MedicalData[Quarter],K4,MedicalData[Hospital Transportation],"Yes")),0))) | D95: =IF(OR(B95=0,B95=""),"-",IFERROR(ROUND(AVERAGEIF(MedicalData[Month],E4,MedicalData[Age]),0),"-")) | E95: =IF(OR(B95=0,B95=""),"-","-") | F95: =IF(OR(B95=0,B95=""),"-","-") | G95: =IF(OR(B95=0,B95=""),"-","-")
A96: TOTAL | B96: =SUM(B91:B95) | C96: =SUM(C91:C95) | D96: =IFERROR(ROUND(IF(B4="Monthly",AVERAGEIF(MedicalData[Month],E4,MedicalData[Age]),IF(B4="Quarterly",AVERAGEIF(MedicalData[Quarter],K4,MedicalData[Age]),AVERAGE(MedicalData[Age]))),0),"-")
A100: =IF(B4="Quarterly","QUARTERLY COMPARISON",IF(B4="Monthly","MONTHLY TRENDS","PERIOD ANALYSIS"))
A102: Period | B102: Incidents | C102: Ambulance | D102: Avg Age | E102: vs Previous
...

Sheet Monthly Stats
A1: MONTHLY STATISTICS
A2: Period: | B2: =Dashboard!B7
A3: Month | B3: Total Cases | C3: Ambulance | D3: Avg Age | E3: Selected
A4: Jan-24 | B4: =COUNTIF(MedicalData[Month],A4) | C4: =COUNTIFS(MedicalData[Month],A4,MedicalData[Hospital Transportation],"Yes") | D4: =IFERROR(ROUND(AVERAGEIF(MedicalData[Month],A4,MedicalData[Age]),0),"") | E4: =IF(A4=Dashboard!E4,"►","")
A5: Feb-24 | B5: =COUNTIF(MedicalData[Month],A5) | C5: =COUNTIFS(MedicalData[Month],A5,MedicalData[Hospital Transportation],"Yes") | D5: =IFERROR(ROUND(AVERAGEIF(MedicalData[Month],A5,MedicalData[Age]),0),"") | E5: =IF(A5=Dashboard!E4,"►","")
A6: Mar-24 | B6: =COUNTIF(MedicalData[Month],A6) | C6: =COUNTIFS(MedicalData[Month],A6,MedicalData[Hospital Transportation],"Yes") | D6: =IFERROR(ROUND(AVERAGEIF(MedicalData[Month],A6,MedicalData[Age]),0),"") | E6: =IF(A6=Dashboard!E4,"►","")
A7: Apr-24 | B7: =COUNTIF(MedicalData[Month],A7) | C7: =COUNTIFS(MedicalData[Month],A7,MedicalData[Hospital Transportation],"Yes") | D7: =IFERROR(ROUND(AVERAGEIF(MedicalData[Month],A7,MedicalData[Age]),0),"") | E7: =IF(A7=Dashboard!E4,"►","")
A8: May-24 | B8: =COUNTIF(MedicalData[Month],A8) | C8: =COUNTIFS(MedicalData[Month],A8,MedicalData[Hospital Transportation],"Yes") | D8: =IFERROR(ROUND(AVERAGEIF(MedicalData[Month],A8,MedicalData[Age]),0),"") | E8: =IF(A8=Dashboard!E4,"►","")
A9: Jun-24 | B9: =COUNTIF(MedicalData[Month],A9) | C9: =COUNTIFS(MedicalData[Month],A9,MedicalData[Hospital Transportation],"Yes") | D9: =IFERROR(ROUND(AVERAGEIF(MedicalData[Month],A9,MedicalData[Age]),0),"") | E9: =IF(A9=Dashboard!E4,"►","")
A10: Jul-24 | B10: =COUNTIF(MedicalData[Month],A10) | C10: =COUNTIFS(MedicalData[Month],A10,MedicalData[Hospital Transportation],"Yes") | D10: =IFERROR(ROUND(AVERAGEIF(MedicalData[Month],A10,MedicalData[Age]),0),"") | E10: =IF(A10=Dashboard!E4,"►","")
A11: Aug-24 | B11: =COUNTIF(MedicalData[Month],A11) | C11: =COUNTIFS(MedicalData[Month],A11,MedicalData[Hospital Transportation],"Yes") | D11: =IFERROR(ROUND(AVERAGEIF(MedicalData[Month],A11,MedicalData[Age]),0),"") | E11: =IF(A11=Dashboard!E4,"►","")
A12: Sep-24 | B12: =COUNTIF(MedicalData[Month],A12) | C12: =COUNTIFS(MedicalData[Month],A12,MedicalData[Hospital Transportation],"Yes") | D12: =IFERROR(ROUND(AVERAGEIF(MedicalData[Month],A12,MedicalData[Age]),0),"") | E12: =IF(A12=Dashboard!E4,"►","")
A13: Oct-24 | B13: =COUNTIF(MedicalData[Month],A13) | C13: =COUNTIFS(MedicalData[Month],A13,MedicalData[Hospital Transportation],"Yes") | D13: =IFERROR(ROUND(AVERAGEIF(MedicalData[Month],A13,MedicalData[Age]),0),"") | E13: =IF(A13=Dashboard!E4,"►","")
A14: Nov-24 | B14: =COUNTIF(MedicalData[Month],A14) | C14: =COUNTIFS(MedicalData[Month],A14,MedicalData[Hospital Transportation],"Yes") | D14: =IFERROR(ROUND(AVERAGEIF(MedicalData[Month],A14,MedicalData[Age]),0),"") | E14: =IF(A14=Dashboard!E4,"►","")
A15: Dec-24 | B15: =COUNTIF(MedicalData[Month],A15) | C15: =COUNTIFS(MedicalData[Month],A15,MedicalData[Hospital Transportation],"Yes") | D15: =IFERROR(ROUND(AVERAGEIF(MedicalData[Month],A15,MedicalData[Age]),0),"") | E15: =IF(A15=Dashboard!E4,"►","")
A16: Jan-25 | B16: =COUNTIF(MedicalData[Month],A16) | C16: =COUNTIFS(MedicalData[Month],A16,MedicalData[Hospital Transportation],"Yes") | D16: =IFERROR(ROUND(AVERAGEIF(MedicalData[Month],A16,MedicalData[Age]),0),"") | E16: =IF(A16=Dashboard!E4,"►","")
A17: Feb-25 | B17: =COUNTIF(MedicalData[Month],A17) | C17: =COUNTIFS(MedicalData[Month],A17,MedicalData[Hospital Transportation],"Yes") | D17: =IFERROR(ROUND(AVERAGEIF(MedicalData[Month],A17,MedicalData[Age]),0),"") | E17: =IF(A17=Dashboard!E4,"►","")
A18: Mar-25 | B18: =COUNTIF(MedicalData[Month],A18) | C18: =COUNTIFS(MedicalData[Month],A18,MedicalData[Hospital Transportation],"Yes") | D18: =IFERROR(ROUND(AVERAGEIF(MedicalData[Month],A18,MedicalData[Age]),0),"") | E18: =IF(A18=Dashboard!E4,"►","")
A19: Apr-25 | B19: =COUNTIF(MedicalData[Month],A19) | C19: =COUNTIFS(MedicalData[Month],A19,MedicalData[Hospital Transportation],"Yes") | D19: =IFERROR(ROUND(AVERAGEIF(MedicalData[Month],A19,MedicalData[Age]),0),"") | E19: =IF(A19=Dashboard!E4,"►","")
A20: May-25 | B20: =COUNTIF(MedicalData[Month],A20) | C20: =COUNTIFS(MedicalData[Month],A20,MedicalData[Hospital Transportation],"Yes") | D20: =IFERROR(ROUND(AVERAGEIF(MedicalData[Month],A20,MedicalData[Age]),0),"") | E20: =IF(A20=Dashboard!E4,"►","")
A21: Jun-25 | B21: =COUNTIF(MedicalData[Month],A21) | C21: =COUNTIFS(MedicalData[Month],A21,MedicalData[Hospital Transportation],"Yes") | D21: =IFERROR(ROUND(AVERAGEIF(MedicalData[Month],A21,MedicalData[Age]),0),"") | E21: =IF(A21=Dashboard!E4,"►","")
A22: Jul-25 | B22: =COUNTIF(MedicalData[Month],A22) | C22: =COUNTIFS(MedicalData[Month],A22,MedicalData[Hospital Transportation],"Yes") | D22: =IFERROR(ROUND(AVERAGEIF(MedicalData[Month],A22,MedicalData[Age]),0),"") | E22: =IF(A22=Dashboard!E4,"►","")
A23: Aug-25 | B23: =COUNTIF(MedicalData[Month],A23) | C23: =COUNTIFS(MedicalData[Month],A23,MedicalData[Hospital Transportation],"Yes") | D23: =IFERROR(ROUND(AVERAGEIF(MedicalData[Month],A23,MedicalData[Age]),0),"") | E23: =IF(A23=Dashboard!E4,"►","")
A24: Sep-25 | B24: =COUNTIF(MedicalData[Month],A24) | C24: =COUNTIFS(MedicalData[Month],A24,MedicalData[Hospital Transportation],"Yes") | D24: =IFERROR(ROUND(AVERAGEIF(MedicalData[Month],A24,MedicalData[Age]),0),"") | E24: =IF(A24=Dashboard!E4,"►","")
A25: Oct-25 | B25: =COUNTIF(MedicalData[Month],A25) | C25: =COUNTIFS(MedicalData[Month],A25,MedicalData[Hospital Transportation],"Yes") | D25: =IFERROR(ROUND(AVERAGEIF(MedicalData[Month],A25,MedicalData[Age]),0),"") | E25: =IF(A25=Dashboard!E4,"►","")
A26: Nov-25 | B26: =COUNTIF(MedicalData[Month],A26) | C26: =COUNTIFS(MedicalData[Month],A26,MedicalData[Hospital Transportation],"Yes") | D26: =IFERROR(ROUND(AVERAGEIF(MedicalData[Month],A26,MedicalData[Age]),0),"") | E26: =IF(A26=Dashboard!E4,"►","")
A27: Dec-25 | B27: =COUNTIF(MedicalData[Month],A27) | C27: =COUNTIFS(MedicalData[Month],A27,MedicalData[Hospital Transportation],"Yes") | D27: =IFERROR(ROUND(AVERAGEIF(MedicalData[Month],A27,MedicalData[Age]),0),"") | E27: =IF(A27=Dashboard!E4,"►","")

Sheet Venue Analysis
A1: VENUE RISK ANALYSIS
A2: Period: | B2: =Dashboard!B7
A3: Venue | B3: Count | C3: % of Total | D3: Risk Level | E3: Status
A4: Skate Park | B4: =IF(Dashboard!B4="Weekly",SUMPRODUCT((MedicalData[Month]=Dashboard!E4)*(INT((DAY(MedicalData[Date])-1)/7)+1=Dashboard!$M$4)*(MedicalData[Site]=A4)*1),IF(Dashboard!B4="Monthly",COUNTIFS(MedicalData[Site],A4,MedicalData[Month],Dashboard!E4),IF(Dashboard!B4="Quarterly",COUNTIFS(MedicalData[Site],A4,MedicalData[Quarter],Dashboard!K4),COUNTIF(MedicalData[Site],A4)))) | C4: =IF(SUM($B$4:$B$19)=0,0,B4/SUM($B$4:$B$19)) | D4: =IF(B4>=8,"🔴 HIGH",IF(B4>=5,"🟡 MEDIUM","🟢 LOW")) | E4: =IF(B4>=8,"Immediate Action Required",IF(B4>=5,"Monitor Closely","Normal"))
A5: 5 A side | B5: =IF(Dashboard!B4="Weekly",SUMPRODUCT((MedicalData[Month]=Dashboard!E4)*(INT((DAY(MedicalData[Date])-1)/7)+1=Dashboard!$M$4)*(MedicalData[Site]=A5)*1),IF(Dashboard!B4="Monthly",COUNTIFS(MedicalData[Site],A5,MedicalData[Month],Dashboard!E4),IF(Dashboard!B4="Quarterly",COUNTIFS(MedicalData[Site],A5,MedicalData[Quarter],Dashboard!K4),COUNTIF(MedicalData[Site],A5)))) | C5: =IF(SUM($B$4:$B$19)=0,0,B5/SUM($B$4:$B$19)) | D5: =IF(B5>=8,"🔴 HIGH",IF(B5>=5,"🟡 MEDIUM","🟢 LOW")) | E5: =IF(B5>=8,"Immediate Action Required",IF(B5>=5,"Monitor Closely","Normal"))
A6: Basketball | B6: =IF(Dashboard!B4="Weekly",SUMPRODUCT((MedicalData[Month]=Dashboard!E4)*(INT((DAY(MedicalData[Date])-1)/7)+1=Dashboard!$M$4)*(MedicalData[Site]=A6)*1),IF(Dashboard!B4="Monthly",COUNTIFS(MedicalData[Site],A6,MedicalData[Month],Dashboard!E4),IF(Dashboard!B4="Quarterly",COUNTIFS(MedicalData[Site],A6,MedicalData[Quarter],Dashboard!K4),COUNTIF(MedicalData[Site],A6)))) | C6: =IF(SUM($B$4:$B$19)=0,0,B6/SUM($B$4:$B$19)) | D6: =IF(B6>=8,"🔴 HIGH",IF(B6>=5,"🟡 MEDIUM","🟢 LOW")) | E6: =IF(B6>=8,"Immediate Action Required",IF(B6>=5,"Monitor Closely","Normal"))
A7: Outdoor gym | B7: =IF(Dashboard!B4="Weekly",SUMPRODUCT((MedicalData[Month]=Dashboard!E4)*(INT((DAY(MedicalData[Date])-1)/7)+1=Dashboard!$M$4)*(MedicalData[Site]=A7)*1),IF(Dashboard!B4="Monthly",COUNTIFS(MedicalData[Site],A7,MedicalData[Month],Dashboard!E4),IF(Dashboard!B4="Quarterly",COUNTIFS(MedicalData[Site],A7,MedicalData[Quarter],Dashboard!K4),COUNTIF(MedicalData[Site],A7)))) | C7: =IF(SUM($B$4:$B$19)=0,0,B7/SUM($B$4:$B$19)) | D7: =IF(B7>=8,"🔴 HIGH",IF(B7>=5,"🟡 MEDIUM","🟢 LOW")) | E7: =IF(B7>=8,"Immediate Action Required",IF(B7>=5,"Monitor Closely","Normal"))
A8: JDI Studio | B8: =IF(Dashboard!B4="Weekly",SUMPRODUCT((MedicalData[Month]=Dashboard!E4)*(INT((DAY(MedicalData[Date])-1)/7)+1=Dashboard!$M$4)*(MedicalData[Site]=A8)*1),IF(Dashboard!B4="Monthly",COUNTIFS(MedicalData[Site],A8,MedicalData[Month],Dashboard!E4),IF(Dashboard!B4="Quarterly",COUNTIFS(MedicalData[Site],A8,MedicalData[Quarter],Dashboard!K4),COUNTIF(MedicalData[Site],A8)))) | C8: =IF(SUM($B$4:$B$19)=0,0,B8/SUM($B$4:$B$19)) | D8: =IF(B8>=8,"🔴 HIGH",IF(B8>=5,"🟡 MEDIUM","🟢 LOW")) | E8: =IF(B8>=8,"Immediate Action Required",IF(B8>=5,"Monitor Closely","Normal"))
A9: PHINDA Studio | B9: =IF(Dashboard!B4="Weekly",SUMPRODUCT((MedicalData[Month]=Dashboard!E4)*(INT((DAY(MedicalData[Date])-1)/7)+1=Dashboard!$M$4)*(MedicalData[Site]=A9)*1),IF(Dashboard!B4="Monthly",COUNTIFS(MedicalData[Site],A9,MedicalData[Month],Dashboard!E4),IF(Dashboard!B4="Quarterly",COUNTIFS(MedicalData[Site],A9,MedicalData[Quarter],Dashboard!K4),COUNTIF(MedicalData[Site],A9)))) | C9: =IF(SUM($B$4:$B$19)=0,0,B9/SUM($B$4:$B$19)) | D9: =IF(B9>=8,"🔴 HIGH",IF(B9>=5,"🟡 MEDIUM","🟢 LOW")) | E9: =IF(B9>=8,"Immediate Action Required",IF(B9>=5,"Monitor Closely","Normal"))
A10: PHAMBILI Studio | B10: =IF(Dashboard!B4="Weekly",SUMPRODUCT((MedicalData[Month]=Dashboard!E4)*(INT((DAY(MedicalData[Date])-1)/7)+1=Dashboard!$M$4)*(MedicalData[Site]=A10)*1),IF(Dashboard!B4="Monthly",COUNTIFS(MedicalData[Site],A10,MedicalData[Month],Dashboard!E4),IF(Dashboard!B4="Quarterly",COUNTIFS(MedicalData[Site],A10,MedicalData[Quarter],Dashboard!K4),COUNTIF(MedicalData[Site],A10)))) | C10: =IF(SUM($B$4:$B$19)=0,0,B10/SUM($B$4:$B$19)) | D10: =IF(B10>=8,"🔴 HIGH",IF(B10>=5,"🟡 MEDIUM","🟢 LOW")) | E10: =IF(B10>=8,"Immediate Action Required",IF(B10>=5,"Monitor Closely","Normal"))
A11: 11- A side | B11: =IF(Dashboard!B4="Weekly",SUMPRODUCT((MedicalData[Month]=Dashboard!E4)*(INT((DAY(MedicalData[Date])-1)/7)+1=Dashboard!$M$4)*(MedicalData[Site]=A11)*1),IF(Dashboard!B4="Monthly",COUNTIFS(MedicalData[Site],A11,MedicalData[Month],Dashboard!E4),IF(Dashboard!B4="Quarterly",COUNTIFS(MedicalData[Site],A11,MedicalData[Quarter],Dashboard!K4),COUNTIF(MedicalData[Site],A11)))) | C11: =IF(SUM($B$4:$B$19)=0,0,B11/SUM($B$4:$B$19)) | D11: =IF(B11>=8,"🔴 HIGH",IF(B11>=5,"🟡 MEDIUM","🟢 LOW")) | E11: =IF(B11>=8,"Immediate Action Required",IF(B11>=5,"Monitor Closely","Normal"))
A12: Athletics track | B12: =IF(Dashboard!B4="Weekly",SUMPRODUCT((MedicalData[Month]=Dashboard!E4)*(INT((DAY(MedicalData[Date])-1)/7)+1=Dashboard!$M$4)*(MedicalData[Site]=A12)*1),IF(Dashboard!B4="Monthly",COUNTIFS(MedicalData[Site],A12,MedicalData[Month],Dashboard!E4),IF(Dashboard!B4="Quarterly",COUNTIFS(MedicalData[Site],A12,MedicalData[Quarter],Dashboard!K4),COUNTIF(MedicalData[Site],A12)))) | C12: =IF(SUM($B$4:$B$19)=0,0,B12/SUM($B$4:$B$19)) | D12: =IF(B12>=8,"🔴 HIGH",IF(B12>=5,"🟡 MEDIUM","🟢 LOW")) | E12: =IF(B12>=8,"Immediate Action Required",IF(B12>=5,"Monitor Closely","Normal"))
A13: Registration area | B13: =IF(Dashboard!B4="Weekly",SUMPRODUCT((MedicalData[Month]=Dashboard!E4)*(INT((DAY(MedicalData[Date])-1)/7)+1=Dashboard!$M$4)*(MedicalData[Site]=A13)*1),IF(Dashboard!B4="Monthly",COUNTIFS(MedicalData[Site],A13,MedicalData[Month],Dashboard!E4),IF(Dashboard!B4="Quarterly",COUNTIFS(MedicalData[Site],A13,MedicalData[Quarter],Dashboard!K4),COUNTIF(MedicalData[Site],A13)))) | C13: =IF(SUM($B$4:$B$19)=0,0,B13/SUM($B$4:$B$19)) | D13: =IF(B13>=8,"🔴 HIGH",IF(B13>=5,"🟡 MEDIUM","🟢 LOW")) | E13: =IF(B13>=8,"Immediate Action Required",IF(B13>=5,"Monitor Closely","Normal"))
A14: Car parking | B14: =IF(Dashboard!B4="Weekly",SUMPRODUCT((MedicalData[Month]=Dashboard!E4)*(INT((DAY(MedicalData[Date])-1)/7)+1=Dashboard!$M$4)*(MedicalData[Site]=A14)*1),IF(Dashboard!B4="Monthly",COUNTIFS(MedicalData[Site],A14,MedicalData[Month],Dashboard!E4),IF(Dashboard!B4="Quarterly",COUNTIFS(MedicalData[Site],A14,MedicalData[Quarter],Dashboard!K4),COUNTIF(MedicalData[Site],A14)))) | C14: =IF(SUM($B$4:$B$19)=0,0,B14/SUM($B$4:$B$19)) | D14: =IF(B14>=8,"🔴 HIGH",IF(B14>=5,"🟡 MEDIUM","🟢 LOW")) | E14: =IF(B14>=8,"Immediate Action Required",IF(B14>=5,"Monitor Closely","Normal"))
A15: Change Rooms | B15: =IF(Dashboard!B4="Weekly",SUMPRODUCT((MedicalData[Month]=Dashboard!E4)*(INT((DAY(MedicalData[Date])-1)/7)+1=Dashboard!$M$4)*(MedicalData[Site]=A15)*1),IF(Dashboard!B4="Monthly",COUNTIFS(MedicalData[Site],A15,MedicalData[Month],Dashboard!E4),IF(Dashboard!B4="Quarterly",COUNTIFS(MedicalData[Site],A15,MedicalData[Quarter],Dashboard!K4),COUNTIF(MedicalData[Site],A15)))) | C15: =IF(SUM($B$4:$B$19)=0,0,B15/SUM($B$4:$B$19)) | D15: =IF(B15>=8,"🔴 HIGH",IF(B15>=5,"🟡 MEDIUM","🟢 LOW")) | E15: =IF(B15>=8,"Immediate Action Required",IF(B15>=5,"Monitor Closely","Normal"))
A16: Equipment Rooms | B16: =IF(Dashboard!B4="Weekly",SUMPRODUCT((MedicalData[Month]=Dashboard!E4)*(INT((DAY(MedicalData[Date])-1)/7)+1=Dashboard!$M$4)*(MedicalData[Site]=A16)*1),IF(Dashboard!B4="Monthly",COUNTIFS(MedicalData[Site],A16,MedicalData[Month],Dashboard!E4),IF(Dashboard!B4="Quarterly",COUNTIFS(MedicalData[Site],A16,MedicalData[Quarter],Dashboard!K4),COUNTIF(MedicalData[Site],A16)))) | C16: =IF(SUM($B$4:$B$19)=0,0,B16/SUM($B$4:$B$19)) | D16: =IF(B16>=8,"🔴 HIGH",IF(B16>=5,"🟡 MEDIUM","🟢 LOW")) | E16: =IF(B16>=8,"Immediate Action Required",IF(B16>=5,"Monitor Closely","Normal"))
A17: 1KM RUN/WALK PATH | B17: =IF(Dashboard!B4="Weekly",SUMPRODUCT((MedicalData[Month]=Dashboard!E4)*(INT((DAY(MedicalData[Date])-1)/7)+1=Dashboard!$M$4)*(MedicalData[Site]=A17)*1),IF(Dashboard!B4="Monthly",COUNTIFS(MedicalData[Site],A17,MedicalData[Month],Dashboard!E4),IF(Dashboard!B4="Quarterly",COUNTIFS(MedicalData[Site],A17,MedicalData[Quarter],Dashboard!K4),COUNTIF(MedicalData[Site],A17)))) | C17: =IF(SUM($B$4:$B$19)=0,0,B17/SUM($B$4:$B$19)) | D17: =IF(B17>=8,"🔴 HIGH",IF(B17>=5,"🟡 MEDIUM","🟢 LOW")) | E17: =IF(B17>=8,"Immediate Action Required",IF(B17>=5,"Monitor Closely","Normal"))
A18: Bleachers | B18: =IF(Dashboard!B4="Weekly",SUMPRODUCT((MedicalData[Month]=Dashboard!E4)*(INT((DAY(MedicalData[Date])-1)/7)+1=Dashboard!$M$4)*(MedicalData[Site]=A18)*1),IF(Dashboard!B4="Monthly",COUNTIFS(MedicalData[Site],A18,MedicalData[Month],Dashboard!E4),IF(Dashboard!B4="Quarterly",COUNTIFS(MedicalData[Site],A18,MedicalData[Quarter],Dashboard!K4),COUNTIF(MedicalData[Site],A18)))) | C18: =IF(SUM($B$4:$B$19)=0,0,B18/SUM($B$4:$B$19)) | D18: =IF(B18>=8,"🔴 HIGH",IF(B18>=5,"🟡 MEDIUM","🟢 LOW")) | E18: =IF(B18>=8,"Immediate Action Required",IF(B18>=5,"Monitor Closely","Normal"))
A19: P GATE | B19: =IF(Dashboard!B4="Weekly",SUMPRODUCT((MedicalData[Month]=Dashboard!E4)*(INT((DAY(MedicalData[Date])-1)/7)+1=Dashboard!$M$4)*(MedicalData[Site]=A19)*1),IF(Dashboard!B4="Monthly",COUNTIFS(MedicalData[Site],A19,MedicalData[Month],Dashboard!E4),IF(Dashboard!B4="Quarterly",COUNTIFS(MedicalData[Site],A19,MedicalData[Quarter],Dashboard!K4),COUNTIF(MedicalData[Site],A19)))) | C19: =IF(SUM($B$4:$B$19)=0,0,B19/SUM($B$4:$B$19)) | D19: =IF(B19>=8,"🔴 HIGH",IF(B19>=5,"🟡 MEDIUM","🟢 LOW")) | E19: =IF(B19>=8,"Immediate Action Required",IF(B19>=5,"Monitor Closely","Normal"))

Sheet Age Analysis
A1: AGE DISTRIBUTION ANALYSIS
A2: Period: | B2: =Dashboard!B7
A3: Age Group | B3: Count | C3: Percentage
A4: 0-12 years | B4: =IF(Dashboard!B4="Weekly",SUMPRODUCT((MedicalData[Month]=Dashboard!E4)*(INT((DAY(MedicalData[Date])-1)/7)+1=Dashboard!$M$4)*(MedicalData[Age]>=0)*(MedicalData[Age]<=12)*1),IF(Dashboard!B4="Monthly",COUNTIFS(MedicalData[Age],">=0",MedicalData[Age],"<=12",MedicalData[Month],Dashboard!E4),IF(Dashboard!B4="Quarterly",COUNTIFS(MedicalData[Age],">=0",MedicalData[Age],"<=12",MedicalData[Quarter],Dashboard!K4),COUNTIFS(MedicalData[Age],">=0",MedicalData[Age],"<=12")))) | C4: =IF(SUM($B$4:$B$8)=0,0,B4/SUM($B$4:$B$8))
A5: 13-17 years | B5: =IF(Dashboard!B4="Weekly",SUMPRODUCT((MedicalData[Month]=Dashboard!E4)*(INT((DAY(MedicalData[Date])-1)/7)+1=Dashboard!$M$4)*(MedicalData[Age]>=13)*(MedicalData[Age]<=17)*1),IF(Dashboard!B4="Monthly",COUNTIFS(MedicalData[Age],">=13",MedicalData[Age],"<=17",MedicalData[Month],Dashboard!E4),IF(Dashboard!B4="Quarterly",COUNTIFS(MedicalData[Age],">=13",MedicalData[Age],"<=17",MedicalData[Quarter],Dashboard!K4),COUNTIFS(MedicalData[Age],">=13",MedicalData[Age],"<=17")))) | C5: =IF(SUM($B$4:$B$8)=0,0,B5/SUM($B$4:$B$8))
A6: 18-25 years | B6: =IF(Dashboard!B4="Weekly",SUMPRODUCT((MedicalData[Month]=Dashboard!E4)*(INT((DAY(MedicalData[Date])-1)/7)+1=Dashboard!$M$4)*(MedicalData[Age]>=18)*(MedicalData[Age]<=25)*1),IF(Dashboard!B4="Monthly",COUNTIFS(MedicalData[Age],">=18",MedicalData[Age],"<=25",MedicalData[Month],Dashboard!E4),IF(Dashboard!B4="Quarterly",COUNTIFS(MedicalData[Age],">=18",MedicalData[Age],"<=25",MedicalData[Quarter],Dashboard!K4),COUNTIFS(MedicalData[Age],">=18",MedicalData[Age],"<=25")))) | C6: =IF(SUM($B$4:$B$8)=0,0,B6/SUM($B$4:$B$8))
A7: 26-35 years | B7: =IF(Dashboard!B4="Weekly",SUMPRODUCT((MedicalData[Month]=Dashboard!E4)*(INT((DAY(MedicalData[Date])-1)/7)+1=Dashboard!$M$4)*(MedicalData[Age]>=26)*(MedicalData[Age]<=35)*1),IF(Dashboard!B4="Monthly",COUNTIFS(MedicalData[Age],">=26",MedicalData[Age],"<=35",MedicalData[Month],Dashboard!E4),IF(Dashboard!B4="Quarterly",COUNTIFS(MedicalData[Age],">=26",MedicalData[Age],"<=35",MedicalData[Quarter],Dashboard!K4),COUNTIFS(MedicalData[Age],">=26",MedicalData[Age],"<=35")))) | C7: =IF(SUM($B$4:$B$8)=0,0,B7/SUM($B$4:$B$8))
A8: 36+ years | B8: =IF(Dashboard!B4="Weekly",SUMPRODUCT((MedicalData[Month]=Dashboard!E4)*(INT((DAY(MedicalData[Date])-1)/7)+1=Dashboard!$M$4)*(MedicalData[Age]>=36)*1),IF(Dashboard!B4="Monthly",COUNTIFS(MedicalData[Age],">=36",MedicalData[Month],Dashboard!E4),IF(Dashboard!B4="Quarterly",COUNTIFS(MedicalData[Age],">=36",MedicalData[Quarter],Dashboard!K4),COUNTIFS(MedicalData[Age],">=36")))) | C8: =IF(SUM($B$4:$B$8)=0,0,B8/SUM($B$4:$B$8))

Sheet Injury Analysis
A1: INJURY TYPE ANALYSIS
A2: Period: | B2: =Dashboard!B7
A3: Injury Type | B3: Count | C3: % of Total
A4: Head Injury | B4: =IF(Dashboard!B4="Weekly",SUMPRODUCT((MedicalData[Month]=Dashboard!E4)*(INT((DAY(MedicalData[Date])-1)/7)+1=Dashboard!$M$4)*(ISNUMBER(SEARCH(A4,MedicalData[Specific injuries treated])))*1),IF(Dashboard!B4="Monthly",COUNTIFS(MedicalData[Specific injuries treated],"*"&A4&"*",MedicalData[Month],Dashboard!E4),IF(Dashboard!B4="Quarterly",COUNTIFS(MedicalData[Specific injuries treated],"*"&A4&"*",MedicalData[Quarter],Dashboard!K4),COUNTIF(MedicalData[Specific injuries treated],"*"&A4&"*")))) | C4: =IF(SUM($B$4:$B$23)=0,0,B4/SUM($B$4:$B$23))
A5: Neck Injury | B5: =IF(Dashboard!B4="Weekly",SUMPRODUCT((MedicalData[Month]=Dashboard!E4)*(INT((DAY(MedicalData[Date])-1)/7)+1=Dashboard!$M$4)*(ISNUMBER(SEARCH(A5,MedicalData[Specific injuries treated])))*1),IF(Dashboard!B4="Monthly",COUNTIFS(MedicalData[Specific injuries treated],"*"&A5&"*",MedicalData[Month],Dashboard!E4),IF(Dashboard!B4="Quarterly",COUNTIFS(MedicalData[Specific injuries treated],"*"&A5&"*",MedicalData[Quarter],Dashboard!K4),COUNTIF(MedicalData[Specific injuries treated],"*"&A5&"*")))) | C5: =IF(SUM($B$4:$B$23)=0,0,B5/SUM($B$4:$B$23))
A6: Facial Injury | B6: =IF(Dashboard!B4="Weekly",SUMPRODUCT((MedicalData[Month]=Dashboard!E4)*(INT((DAY(MedicalData[Date])-1)/7)+1=Dashboard!$M$4)*(ISNUMBER(SEARCH(A6,MedicalData[Specific injuries treated])))*1),IF(Dashboard!B4="Monthly",COUNTIFS(MedicalData[Specific injuries treated],"*"&A6&"*",MedicalData[Month],Dashboard!E4),IF(Dashboard!B4="Quarterly",COUNTIFS(MedicalData[Specific injuries treated],"*"&A6&"*",MedicalData[Quarter],Dashboard!K4),COUNTIF(MedicalData[Specific injuries treated],"*"&A6&"*")))) | C6: =IF(SUM($B$4:$B$23)=0,0,B6/SUM($B$4:$B$23))
A7: spinal injury | B7: =IF(Dashboard!B4="Weekly",SUMPRODUCT((MedicalData[Month]=Dashboard!E4)*(INT((DAY(MedicalData[Date])-1)/7)+1=Dashboard!$M$4)*(ISNUMBER(SEARCH(A7,MedicalData[Specific injuries treated])))*1),IF(Dashboard!B4="Monthly",COUNTIFS(MedicalData[Specific injuries treated],"*"&A7&"*",MedicalData[Month],Dashboard!E4),IF(Dashboard!B4="Quarterly",COUNTIFS(MedicalData[Specific injuries treated],"*"&A7&"*",MedicalData[Quarter],Dashboard!K4),COUNTIF(MedicalData[Specific injuries treated],"*"&A7&"*")))) | C7: =IF(SUM($B$4:$B$23)=0,0,B7/SUM($B$4:$B$23))
A8: Shoulder | B8: =IF(Dashboard!B4="Weekly",SUMPRODUCT((MedicalData[Month]=Dashboard!E4)*(INT((DAY(MedicalData[Date])-1)/7)+1=Dashboard!$M$4)*(ISNUMBER(SEARCH(A8,MedicalData[Specific injuries treated])))*1),IF(Dashboard!B4="Monthly",COUNTIFS(MedicalData[Specific injuries treated],"*"&A8&"*",MedicalData[Month],Dashboard!E4),IF(Dashboard!B4="Quarterly",COUNTIFS(MedicalData[Specific injuries treated],"*"&A8&"*",MedicalData[Quarter],Dashboard!K4),COUNTIF(MedicalData[Specific injuries treated],"*"&A8&"*")))) | C8: =IF(SUM($B$4:$B$23)=0,0,B8/SUM($B$4:$B$23))
A9: Elbow | B9: =IF(Dashboard!B4="Weekly",SUMPRODUCT((MedicalData[Month]=Dashboard!E4)*(INT((DAY(MedicalData[Date])-1)/7)+1=Dashboard!$M$4)*(ISNUMBER(SEARCH(A9,MedicalData[Specific injuries treated])))*1),IF(Dashboard!B4="Monthly",COUNTIFS(MedicalData[Specific injuries treated],"*"&A9&"*",MedicalData[Month],Dashboard!E4),IF(Dashboard!B4="Quarterly",COUNTIFS(MedicalData[Specific injuries treated],"*"&A9&"*",MedicalData[Quarter],Dashboard!K4),COUNTIF(MedicalData[Specific injuries treated],"*"&A9&"*")))) | C9: =IF(SUM($B$4:$B$23)=0,0,B9/SUM($B$4:$B$23))
A10: Wrist | B10: =IF(Dashboard!B4="Weekly",SUMPRODUCT((MedicalData[Month]=Dashboard!E4)*(INT((DAY(MedicalData[Date])-1)/7)+1=Dashboard!$M$4)*(ISNUMBER(SEARCH(A10,MedicalData[Specific injuries treated])))*1),IF(Dashboard!B4="Monthly",COUNTIFS(MedicalData[Specific injuries treated],"*"&A10&"*",MedicalData[Month],Dashboard!E4),IF(Dashboard!B4="Quarterly",COUNTIFS(MedicalData[Specific injuries treated],"*"&A10&"*",MedicalData[Quarter],Dashboard!K4),COUNTIF(MedicalData[Specific injuries treated],"*"&A10&"*")))) | C10: =IF(SUM($B$4:$B$23)=0,0,B10/SUM($B$4:$B$23))
A11: Hand | B11: =IF(Dashboard!B4="Weekly",SUMPRODUCT((MedicalData[Month]=Dashboard!E4)*(INT((DAY(MedicalData[Date])-1)/7)+1=Dashboard!$M$4)*(ISNUMBER(SEARCH(A11,MedicalData[Specific injuries treated])))*1),IF(Dashboard!B4="Monthly",COUNTIFS(MedicalData[Specific injuries treated],"*"&A11&"*",MedicalData[Month],Dashboard!E4),IF(Dashboard!B4="Quarterly",COUNTIFS(MedicalData[Specific injuries treated],"*"&A11&"*",MedicalData[Quarter],Dashboard!K4),COUNTIF(MedicalData[Specific injuries treated],"*"&A11&"*")))) | C11: =IF(SUM($B$4:$B$23)=0,0,B11/SUM($B$4:$B$23))
A12: Arm | B12: =IF(Dashboard!B4="Weekly",SUMPRODUCT((MedicalData[Month]=Dashboard!E4)*(INT((DAY(MedicalData[Date])-1)/7)+1=Dashboard!$M$4)*(ISNUMBER(SEARCH(A12,MedicalData[Specific injuries treated])))*1),IF(Dashboard!B4="Monthly",COUNTIFS(MedicalData[Specific injuries treated],"*"&A12&"*",MedicalData[Month],Dashboard!E4),IF(Dashboard!B4="Quarterly",COUNTIFS(MedicalData[Specific injuries treated],"*"&A12&"*",MedicalData[Quarter],Dashboard!K4),COUNTIF(MedicalData[Specific injuries treated],"*"&A12&"*")))) | C12: =IF(SUM($B$4:$B$23)=0,0,B12/SUM($B$4:$B$23))
A13: Upper limb Muscle | B13: =IF(Dashboard!B4="Weekly",SUMPRODUCT((MedicalData[Month]=Dashboard!E4)*(INT((DAY(MedicalData[Date])-1)/7)+1=Dashboard!$M$4)*(ISNUMBER(SEARCH(A13,MedicalData[Specific injuries treated])))*1),IF(Dashboard!B4="Monthly",COUNTIFS(MedicalData[Specific injuries treated],"*"&A13&"*",MedicalData[Month],Dashboard!E4),IF(Dashboard!B4="Quarterly",COUNTIFS(MedicalData[Specific injuries treated],"*"&A13&"*",MedicalData[Quarter],Dashboard!K4),COUNTIF(MedicalData[Specific injuries treated],"*"&A13&"*")))) | C13: =IF(SUM($B$4:$B$23)=0,0,B13/SUM($B$4:$B$23))
A14: Chest | B14: =IF(Dashboard!B4="Weekly",SUMPRODUCT((MedicalData[Month]=Dashboard!E4)*(INT((DAY(MedicalData[Date])-1)/7)+1=Dashboard!$M$4)*(ISNUMBER(SEARCH(A14,MedicalData[Specific injuries treated])))*1),IF(Dashboard!B4="Monthly",COUNTIFS(MedicalData[Specific injuries treated],"*"&A14&"*",MedicalData[Month],Dashboard!E4),IF(Dashboard!B4="Quarterly",COUNTIFS(MedicalData[Specific injuries treated],"*"&A14&"*",MedicalData[Quarter],Dashboard!K4),COUNTIF(MedicalData[Specific injuries treated],"*"&A14&"*")))) | C14: =IF(SUM($B$4:$B$23)=0,0,B14/SUM($B$4:$B$23))
A15: Abdominal | B15: =IF(Dashboard!B4="Weekly",SUMPRODUCT((MedicalData[Month]=Dashboard!E4)*(INT((DAY(MedicalData[Date])-1)/7)+1=Dashboard!$M$4)*(ISNUMBER(SEARCH(A15,MedicalData[Specific injuries treated])))*1),IF(Dashboard!B4="Monthly",COUNTIFS(MedicalData[Specific injuries treated],"*"&A15&"*",MedicalData[Month],Dashboard!E4),IF(Dashboard!B4="Quarterly",COUNTIFS(MedicalData[Specific injuries treated],"*"&A15&"*",MedicalData[Quarter],Dashboard!K4),COUNTIF(MedicalData[Specific injuries treated],"*"&A15&"*")))) | C15: =IF(SUM($B$4:$B$23)=0,0,B15/SUM($B$4:$B$23))
A16: Back | B16: =IF(Dashboard!B4="Weekly",SUMPRODUCT((MedicalData[Month]=Dashboard!E4)*(INT((DAY(MedicalData[Date])-1)/7)+1=Dashboard!$M$4)*(ISNUMBER(SEARCH(A16,MedicalData[Specific injuries treated])))*1),IF(Dashboard!B4="Monthly",COUNTIFS(MedicalData[Specific injuries treated],"*"&A16&"*",MedicalData[Month],Dashboard!E4),IF(Dashboard!B4="Quarterly",COUNTIFS(MedicalData[Specific injuries treated],"*"&A16&"*",MedicalData[Quarter],Dashboard!K4),COUNTIF(MedicalData[Specific injuries treated],"*"&A16&"*")))) | C16: =IF(SUM($B$4:$B$23)=0,0,B16/SUM($B$4:$B$23))
A17: Hip | B17: =IF(Dashboard!B4="Weekly",SUMPRODUCT((MedicalData[Month]=Dashboard!E4)*(INT((DAY(MedicalData[Date])-1)/7)+1=Dashboard!$M$4)*(ISNUMBER(SEARCH(A17,MedicalData[Specific injuries treated])))*1),IF(Dashboard!B4="Monthly",COUNTIFS(MedicalData[Specific injuries treated],"*"&A17&"*",MedicalData[Month],Dashboard!E4),IF(Dashboard!B4="Quarterly",COUNTIFS(MedicalData[Specific injuries treated],"*"&A17&"*",MedicalData[Quarter],Dashboard!K4),COUNTIF(MedicalData[Specific injuries treated],"*"&A17&"*")))) | C17: =IF(SUM($B$4:$B$23)=0,0,B17/SUM($B$4:$B$23))
A18: Knee | B18: =IF(Dashboard!B4="Weekly",SUMPRODUCT((MedicalData[Month]=Dashboard!E4)*(INT((DAY(MedicalData[Date])-1)/7)+1=Dashboard!$M$4)*(ISNUMBER(SEARCH(A18,MedicalData[Specific injuries treated])))*1),IF(Dashboard!B4="Monthly",COUNTIFS(MedicalData[Specific injuries treated],"*"&A18&"*",MedicalData[Month],Dashboard!E4),IF(Dashboard!B4="Quarterly",COUNTIFS(MedicalData[Specific injuries treated],"*"&A18&"*",MedicalData[Quarter],Dashboard!K4),COUNTIF(MedicalData[Specific injuries treated],"*"&A18&"*")))) | C18: =IF(SUM($B$4:$B$23)=0,0,B18/SUM($B$4:$B$23))
A19: Ankle | B19: =IF(Dashboard!B4="Weekly",SUMPRODUCT((MedicalData[Month]=Dashboard!E4)*(INT((DAY(MedicalData[Date])-1)/7)+1=Dashboard!$M$4)*(ISNUMBER(SEARCH(A19,MedicalData[Specific injuries treated])))*1),IF(Dashboard!B4="Monthly",COUNTIFS(MedicalData[Specific injuries treated],"*"&A19&"*",MedicalData[Month],Dashboard!E4),IF(Dashboard!B4="Quarterly",COUNTIFS(MedicalData[Specific injuries treated],"*"&A19&"*",MedicalData[Quarter],Dashboard!K4),COUNTIF(MedicalData[Specific injuries treated],"*"&A19&"*")))) | C19: =IF(SUM($B$4:$B$23)=0,0,B19/SUM($B$4:$B$23))
A20: Foot | B20: =IF(Dashboard!B4="Weekly",SUMPRODUCT((MedicalData[Month]=Dashboard!E4)*(INT((DAY(MedicalData[Date])-1)/7)+1=Dashboard!$M$4)*(ISNUMBER(SEARCH(A20,MedicalData[Specific injuries treated])))*1),IF(Dashboard!B4="Monthly",COUNTIFS(MedicalData[Specific injuries treated],"*"&A20&"*",MedicalData[Month],Dashboard!E4),IF(Dashboard!B4="Quarterly",COUNTIFS(MedicalData[Specific injuries treated],"*"&A20&"*",MedicalData[Quarter],Dashboard!K4),COUNTIF(MedicalData[Specific injuries treated],"*"&A20&"*")))) | C20: =IF(SUM($B$4:$B$23)=0,0,B20/SUM($B$4:$B$23))
A21: Lower limb | B21: =IF(Dashboard!B4="Weekly",SUMPRODUCT((MedicalData[Month]=Dashboard!E4)*(INT((DAY(MedicalData[Date])-1)/7)+1=Dashboard!$M$4)*(ISNUMBER(SEARCH(A21,MedicalData[Specific injuries treated])))*1),IF(Dashboard!B4="Monthly",COUNTIFS(MedicalData[Specific injuries treated],"*"&A21&"*",MedicalData[Month],Dashboard!E4),IF(Dashboard!B4="Quarterly",COUNTIFS(MedicalData[Specific injuries treated],"*"&A21&"*",MedicalData[Quarter],Dashboard!K4),COUNTIF(MedicalData[Specific injuries treated],"*"&A21&"*")))) | C21: =IF(SUM($B$4:$B$23)=0,0,B21/SUM($B$4:$B$23))
A22: General | B22: =IF(Dashboard!B4="Weekly",SUMPRODUCT((MedicalData[Month]=Dashboard!E4)*(INT((DAY(MedicalData[Date])-1)/7)+1=Dashboard!$M$4)*(ISNUMBER(SEARCH(A22,MedicalData[Specific injuries treated])))*1),IF(Dashboard!B4="Monthly",COUNTIFS(MedicalData[Specific injuries treated],"*"&A22&"*",MedicalData[Month],Dashboard!E4),IF(Dashboard!B4="Quarterly",COUNTIFS(MedicalData[Specific injuries treated],"*"&A22&"*",MedicalData[Quarter],Dashboard!K4),COUNTIF(MedicalData[Specific injuries treated],"*"&A22&"*")))) | C22: =IF(SUM($B$4:$B$23)=0,0,B22/SUM($B$4:$B$23))
A23: Medical | B23: =IF(Dashboard!B4="Weekly",SUMPRODUCT((MedicalData[Month]=Dashboard!E4)*(INT((DAY(MedicalData[Date])-1)/7)+1=Dashboard!$M$4)*(ISNUMBER(SEARCH(A23,MedicalData[Specific injuries treated])))*1),IF(Dashboard!B4="Monthly",COUNTIFS(MedicalData[Specific injuries treated],"*"&A23&"*",MedicalData[Month],Dashboard!E4),IF(Dashboard!B4="Quarterly",COUNTIFS(MedicalData[Specific injuries treated],"*"&A23&"*",MedicalData[Quarter],Dashboard!K4),COUNTIF(MedicalData[Specific injuries treated],"*"&A23&"*")))) | C23: =IF(SUM($B$4:$B$23)=0,0,B23/SUM($B$4:$B$23))

Sheet Mechanism Analysis
A1: INJURY MECHANISM ANALYSIS
A2: Period: | B2: =Dashboard!B7
A3: Mechanism | B3: Count | C3: % of Total | D3: Prevention Priority
A4: Player-to-Player | B4: =IF(Dashboard!B4="Weekly",SUMPRODUCT((MedicalData[Month]=Dashboard!E4)*(INT((DAY(MedicalData[Date])-1)/7)+1=Dashboard!$M$4)*(MedicalData[History/Mechanism of injury]=A4)*1),IF(Dashboard!B4="Monthly",COUNTIFS(MedicalData[History/Mechanism of injury],A4,MedicalData[Month],Dashboard!E4),IF(Dashboard!B4="Quarterly",COUNTIFS(MedicalData[History/Mechanism of injury],A4,MedicalData[Quarter],Dashboard!K4),COUNTIF(MedicalData[History/Mechanism of injury],A4)))) | C4: =IF(SUM($B$4:$B$24)=0,0,B4/SUM($B$4:$B$24)) | D4: =IF(B4>=5,"🔴 HIGH",IF(B4>=3,"🟡 MEDIUM","🟢 LOW"))
A5: Player-to-Object | B5: =IF(Dashboard!B4="Weekly",SUMPRODUCT((MedicalData[Month]=Dashboard!E4)*(INT((DAY(MedicalData[Date])-1)/7)+1=Dashboard!$M$4)*(MedicalData[History/Mechanism of injury]=A5)*1),IF(Dashboard!B4="Monthly",COUNTIFS(MedicalData[History/Mechanism of injury],A5,MedicalData[Month],Dashboard!E4),IF(Dashboard!B4="Quarterly",COUNTIFS(MedicalData[History/Mechanism of injury],A5,MedicalData[Quarter],Dashboard!K4),COUNTIF(MedicalData[History/Mechanism of injury],A5)))) | C5: =IF(SUM($B$4:$B$24)=0,0,B5/SUM($B$4:$B$24)) | D5: =IF(B5>=5,"🔴 HIGH",IF(B5>=3,"🟡 MEDIUM","🟢 LOW"))
A6: Struck by Equipment | B6: =IF(Dashboard!B4="Weekly",SUMPRODUCT((MedicalData[Month]=Dashboard!E4)*(INT((DAY(MedicalData[Date])-1)/7)+1=Dashboard!$M$4)*(MedicalData[History/Mechanism of injury]=A6)*1),IF(Dashboard!B4="Monthly",COUNTIFS(MedicalData[History/Mechanism of injury],A6,MedicalData[Month],Dashboard!E4),IF(Dashboard!B4="Quarterly",COUNTIFS(MedicalData[History/Mechanism of injury],A6,MedicalData[Quarter],Dashboard!K4),COUNTIF(MedicalData[History/Mechanism of injury],A6)))) | C6: =IF(SUM($B$4:$B$24)=0,0,B6/SUM($B$4:$B$24)) | D6: =IF(B6>=5,"🔴 HIGH",IF(B6>=3,"🟡 MEDIUM","🟢 LOW"))
A7: Slips, Trips and falls | B7: =IF(Dashboard!B4="Weekly",SUMPRODUCT((MedicalData[Month]=Dashboard!E4)*(INT((DAY(MedicalData[Date])-1)/7)+1=Dashboard!$M$4)*(MedicalData[History/Mechanism of injury]=A7)*1),IF(Dashboard!B4="Monthly",COUNTIFS(MedicalData[History/Mechanism of injury],A7,MedicalData[Month],Dashboard!E4),IF(Dashboard!B4="Quarterly",COUNTIFS(MedicalData[History/Mechanism of injury],A7,MedicalData[Quarter],Dashboard!K4),COUNTIF(MedicalData[History/Mechanism of injury],A7)))) | C7: =IF(SUM($B$4:$B$24)=0,0,B7/SUM($B$4:$B$24)) | D7: =IF(B7>=5,"🔴 HIGH",IF(B7>=3,"🟡 MEDIUM","🟢 LOW"))
A8: Falls from Height | B8: =IF(Dashboard!B4="Weekly",SUMPRODUCT((MedicalData[Month]=Dashboard!E4)*(INT((DAY(MedicalData[Date])-1)/7)+1=Dashboard!$M$4)*(MedicalData[History/Mechanism of injury]=A8)*1),IF(Dashboard!B4="Monthly",COUNTIFS(MedicalData[History/Mechanism of injury],A8,MedicalData[Month],Dashboard!E4),IF(Dashboard!B4="Quarterly",COUNTIFS(MedicalData[History/Mechanism of injury],A8,MedicalData[Quarter],Dashboard!K4),COUNTIF(MedicalData[History/Mechanism of injury],A8)))) | C8: =IF(SUM($B$4:$B$24)=0,0,B8/SUM($B$4:$B$24)) | D8: =IF(B8>=5,"🔴 HIGH",IF(B8>=3,"🟡 MEDIUM","🟢 LOW"))
A9: Muscle Strains | B9: =IF(Dashboard!B4="Weekly",SUMPRODUCT((MedicalData[Month]=Dashboard!E4)*(INT((DAY(MedicalData[Date])-1)/7)+1=Dashboard!$M$4)*(MedicalData[History/Mechanism of injury]=A9)*1),IF(Dashboard!B4="Monthly",COUNTIFS(MedicalData[History/Mechanism of injury],A9,MedicalData[Month],Dashboard!E4),IF(Dashboard!B4="Quarterly",COUNTIFS(MedicalData[History/Mechanism of injury],A9,MedicalData[Quarter],Dashboard!K4),COUNTIF(MedicalData[History/Mechanism of injury],A9)))) | C9: =IF(SUM($B$4:$B$24)=0,0,B9/SUM($B$4:$B$24)) | D9: =IF(B9>=5,"🔴 HIGH",IF(B9>=3,"🟡 MEDIUM","🟢 LOW"))
